<?xml version="1.0" encoding="utf-8"?>
<!-- =================================================================================== -->
<!-- |    This document was autogenerated by xacro from volta.xacro                    | -->
<!-- |    EDITING THIS FILE BY HAND IS NOT RECOMMENDED                                 | -->
<!-- =================================================================================== -->
<!--

Copyright (c) 2020, Botsync Pte. Ltd.
All rights reserved.

Redistribution and use in source and binary forms, with or without
modification, are permitted provided that the following conditions are met:
    * Redistributions of source code must retain the above copyright
      notice, this list of conditions and the following disclaimer.
    * Redistributions in binary form must reproduce the above copyright
      notice, this list of conditions and the following disclaimer in the
      documentation and/or other materials provided with the distribution.
    * Neither the name of the Botsync Pte. Ltd. nor the
      names of its contributors may be used to endorse or promote products
      derived from this software without specific prior written permission.

THIS SOFTWARE IS PROVIDED BY THE COPYRIGHT HOLDERS AND CONTRIBUTORS "AS IS" AND
ANY EXPRESS OR IMPLIED WARRANTIES, INCLUDING, BUT NOT LIMITED TO, THE IMPLIED
WARRANTIES OF MERCHANTABILITY AND FITNESS FOR A PARTICULAR PURPOSE ARE
DISCLAIMED. IN NO EVENT SHALL <COPYRIGHT HOLDER> BE LIABLE FOR ANY
DIRECT, INDIRECT, INCIDENTAL, SPECIAL, EXEMPLARY, OR CONSEQUENTIAL DAMAGES
(INCLUDING, BUT NOT LIMITED TO, PROCUREMENT OF SUBSTITUTE GOODS OR SERVICES;
LOSS OF USE, DATA, OR PROFITS; OR BUSINESS INTERRUPTION) HOWEVER CAUSED AND
ON ANY THEORY OF LIABILITY, WHETHER IN CONTRACT, STRICT LIABILITY, OR TORT
(INCLUDING NEGLIGENCE OR OTHERWISE) ARISING IN ANY WAY OUT OF THE USE OF THIS
SOFTWARE, EVEN IF ADVISED OF THE POSSIBILITY OF SUCH DAMAGE.

-->
<robot name="volta_robot" 
xmlns:body="http://playerstage.sourceforge.net/gazebo/xmlschema/#body" 
xmlns:controller="http://playerstage.sourceforge.net/gazebo/xmlschema/#controller" xmlns:gazebo="http://playerstage.sourceforge.net/gazebo/xmlschema/#gz" xmlns:geom="http://playerstage.sourceforge.net/gazebo/xmlschema/#geom" xmlns:interface="http://playerstage.sourceforge.net/gazebo/xmlschema/#interface" xmlns:joint="http://playerstage.sourceforge.net/gazebo/xmlschema/#joint" xmlns:model="http://playerstage.sourceforge.net/gazebo/xmlschema/#model" xmlns:physics="http://playerstage.sourceforge.net/gazebo/xmlschema/#physics" xmlns:renderable="http://playerstage.sourceforge.net/gazebo/xmlschema/#renderable" xmlns:rendering="http://playerstage.sourceforge.net/gazebo/xmlschema/#rendering" xmlns:sensor="http://playerstage.sourceforge.net/gazebo/xmlschema/#sensor" xmlns:xi="http://www.w3.org/2001/XInclude">
  <material name="blue">
    <color rgba="0 0 0.8 1"/>
  </material>
  <material name="silver">
    <color rgba="0.75 0.75 0.75 1"/>
  </material>
  <material name="grey">
    <color rgba="0.824 0.824 0.824 1"/>
  </material>
  <material name="black">
    <color rgba="0.260 0.260 0.300 1"/>
  </material>
  <material name="orange">
    <color rgba="0.999 0.547 0 1"/>
  </material>
  <material name="red">
    <color rgba="0.543 0 0 1"/>
  </material>
  <!-- links      		mesh_no
   base           		0
   shoulder       		1
   arm            		2
   forearm        		3
   wrist          		4
   arm_mico       		5
   arm_half1 (7dof)		6
   arm_half2 (7dof)		7
   wrist_spherical_1  8
   wrist_spherical_2  9

   hand 3 finger  		55
   hand_2finger   		56
   finger_proximal		57
   finger_distal      58
-->
  <!-- links      		mesh_no
   base           		0
   shoulder       		1
   arm            		2
   forearm        		3
   wrist          		4
   arm_mico       		5
   arm_half1 (7dof)		6
   arm_half2 (7dof)		7
   wrist_spherical_1  8
   wrist_spherical_2  9

   hand 3 finger  		55
   hand_2finger   		56
   finger_proximal		57
   finger_distal      58
-->
  <!-- Footprint -->
  <link name="footprint"/>
  <!-- Joint from footprint to base link(chassis) -->
  <joint name="base_footprint_joint" type="fixed">
    <origin rpy="0 0 0" xyz="0 0 0.035"/>
    <parent link="base_link"/>
    <child link="footprint"/>
  </joint>
  <!-- Chassis a.k.a base_link -->
  <link name="base_link">
    <visual name="visual_base">
      <origin rpy="0 0 0" xyz="0 0 0"/>
      <geometry>
        <mesh filename="package://volta_description/meshes/volta.dae"/>
      </geometry>
    </visual>
    <visual name="visual_logo">
      <origin rpy="0 0 0" xyz="0 0 0"/>
      <geometry>
        <mesh filename="package://volta_description/meshes/volta_logo.dae"/>
      </geometry>
    </visual>
    <collision>
      <origin rpy="0 0 0" xyz="0 0 0"/>
      <geometry>
        <mesh filename="package://volta_description/meshes/volta.dae"/>
      </geometry>
    </collision>
    <inertial>
      <origin xyz="0.00701 0.0000 0.08382"/>
      <mass value="20.0"/>
      <inertia ixx="0.41802" ixy="0" ixz="0.00305" iyy="0.50105" iyz="0" izz="0.60276"/>
    </inertial>
  </link>
  <!-- Wheel Link -->
  <link name="right_wheel">
    <visual>
      <origin rpy="1.570796327 0 0" xyz="0 0 0"/>
      <geometry>
        <cylinder length="0.02" radius="0.0425"/>
      </geometry>
      <material name="red"/>
    </visual>
    <collision>
      <origin rpy="1.570796327 0 0" xyz="0 0 0"/>
      <geometry>
        <cylinder length="0.02" radius="0.0425"/>
      </geometry>
    </collision>
    <inertial>
      <mass value="0.5"/>
      <origin rpy="0 0 0" xyz="0 0 0"/>
      <inertia ixx="0.0003" ixy="0.0" ixz="0.0" iyy="0.0005" iyz="0.0" izz="0.0003"/>
    </inertial>
  </link>
  <gazebo reference="right_wheel">
    <material>Gazebo/Red</material>
    <mu1 value="1400"/>
    <mu2 value="600"/>
    <kp value="3100000.0"/>
    <kd value="1.0"/>
    <fdir1 value="1 0 0"/>
  </gazebo>
  <!-- Wheel Joint -->
  <joint name="right_wheel_joint" type="continuous">
    <parent link="base_link"/>
    <child link="right_wheel"/>
    <origin rpy="0 0 0" xyz="0.0 -0.1604 0.0264"/>
    <axis xyz="0 1 0"/>
  </joint>
  <!-- Wheel Transmission -->
  <transmission name="right_wheel_transmission" type="SimpleTransmission">
    <type>transmission_interface/SimpleTransmission</type>
    <joint name="right_wheel_joint">
      <hardwareInterface>hardware_interface/VelocityJointInterface</hardwareInterface>
    </joint>
    <actuator name="right_motor">
      <mechanicalReduction>1</mechanicalReduction>
    </actuator>
  </transmission>
  <!-- Wheel Link -->
  <link name="left_wheel">
    <visual>
      <origin rpy="1.570796327 0 0" xyz="0 0 0"/>
      <geometry>
        <cylinder length="0.02" radius="0.0425"/>
      </geometry>
      <material name="red"/>
    </visual>
    <collision>
      <origin rpy="1.570796327 0 0" xyz="0 0 0"/>
      <geometry>
        <cylinder length="0.02" radius="0.0425"/>
      </geometry>
    </collision>
    <inertial>
      <mass value="0.5"/>
      <origin rpy="0 0 0" xyz="0 0 0"/>
      <inertia ixx="0.0003" ixy="0.0" ixz="0.0" iyy="0.0005" iyz="0.0" izz="0.0003"/>
    </inertial>
  </link>
  <gazebo reference="left_wheel">
    <material>Gazebo/Red</material>
    <mu1 value="1400"/>
    <mu2 value="600"/>
    <kp value="3100000.0"/>
    <kd value="1.0"/>
    <fdir1 value="1 0 0"/>
  </gazebo>
  <!-- Wheel Joint -->
  <joint name="left_wheel_joint" type="continuous">
    <parent link="base_link"/>
    <child link="left_wheel"/>
    <origin rpy="0 0 0" xyz="0.0 0.1604 0.0264"/>
    <axis xyz="0 1 0"/>
  </joint>
  <!-- Wheel Transmission -->
  <transmission name="left_wheel_transmission" type="SimpleTransmission">
    <type>transmission_interface/SimpleTransmission</type>
    <joint name="left_wheel_joint">
      <hardwareInterface>hardware_interface/VelocityJointInterface</hardwareInterface>
    </joint>
    <actuator name="left_motor">
      <mechanicalReduction>1</mechanicalReduction>
    </actuator>
  </transmission>
  <!-- Caster Joint -->
  <link name="caster_front_left_link">
    <visual>
      <origin rpy="0 0 0" xyz="0.0 0.0 0.0"/>
      <geometry>
        <sphere radius="0.015"/>
      </geometry>
      <material name="Black"/>
    </visual>
    <collision>
      <geometry>
        <sphere radius="0.015"/>
      </geometry>
      <origin rpy="0 0 0" xyz="0 0 0"/>
    </collision>
    <inertial>
      <mass value="0.1"/>
      <origin xyz="0 0 0"/>
      <inertia ixx="0.0001" ixy="0.0" ixz="0.0" iyy="0.0001" iyz="0.0" izz="0.0001"/>
    </inertial>
  </link>
  <!-- Caster Joint -->
  <joint name="caster_front_left_joint" type="fixed">
    <parent link="base_link"/>
    <child link="caster_front_left_link"/>
    <origin rpy="0 0 0" xyz="0.15925 0.121 -0.0008"/>
  </joint>
  <gazebo reference="caster_front_left_link">
    <material>Gazebo/DarkGrey</material>
    <turnGravityOff>false</turnGravityOff>
    <mu1 value="0.1"/>
    <mu2 value="0.1"/>
    <kp value="10000000.0"/>
    <kd value="1.0"/>
  </gazebo>
  <!-- Caster Joint -->
  <link name="caster_front_right_link">
    <visual>
      <origin rpy="0 0 0" xyz="0.0 0.0 0.0"/>
      <geometry>
        <sphere radius="0.015"/>
      </geometry>
      <material name="Black"/>
    </visual>
    <collision>
      <geometry>
        <sphere radius="0.015"/>
      </geometry>
      <origin rpy="0 0 0" xyz="0 0 0"/>
    </collision>
    <inertial>
      <mass value="0.1"/>
      <origin xyz="0 0 0"/>
      <inertia ixx="0.0001" ixy="0.0" ixz="0.0" iyy="0.0001" iyz="0.0" izz="0.0001"/>
    </inertial>
  </link>
  <!-- Caster Joint -->
  <joint name="caster_front_right_joint" type="fixed">
    <parent link="base_link"/>
    <child link="caster_front_right_link"/>
    <origin rpy="0 0 0" xyz="0.15925 -0.121 -0.0008"/>
  </joint>
  <gazebo reference="caster_front_right_link">
    <material>Gazebo/DarkGrey</material>
    <turnGravityOff>false</turnGravityOff>
    <mu1 value="0.1"/>
    <mu2 value="0.1"/>
    <kp value="10000000.0"/>
    <kd value="1.0"/>
  </gazebo>
  <!-- Caster Joint -->
  <link name="caster_rear_right_link">
    <visual>
      <origin rpy="0 0 0" xyz="0.0 0.0 0.0"/>
      <geometry>
        <sphere radius="0.015"/>
      </geometry>
      <material name="Black"/>
    </visual>
    <collision>
      <geometry>
        <sphere radius="0.015"/>
      </geometry>
      <origin rpy="0 0 0" xyz="0 0 0"/>
    </collision>
    <inertial>
      <mass value="0.1"/>
      <origin xyz="0 0 0"/>
      <inertia ixx="0.0001" ixy="0.0" ixz="0.0" iyy="0.0001" iyz="0.0" izz="0.0001"/>
    </inertial>
  </link>
  <!-- Caster Joint -->
  <joint name="caster_rear_right_joint" type="fixed">
    <parent link="base_link"/>
    <child link="caster_rear_right_link"/>
    <origin rpy="0 0 0" xyz="-0.15925 -0.121 -0.0008"/>
  </joint>
  <gazebo reference="caster_rear_right_link">
    <material>Gazebo/DarkGrey</material>
    <turnGravityOff>false</turnGravityOff>
    <mu1 value="0.1"/>
    <mu2 value="0.1"/>
    <kp value="10000000.0"/>
    <kd value="1.0"/>
  </gazebo>
  <!-- Caster Joint -->
  <link name="caster_rear_left_link">
    <visual>
      <origin rpy="0 0 0" xyz="0.0 0.0 0.0"/>
      <geometry>
        <sphere radius="0.015"/>
      </geometry>
      <material name="Black"/>
    </visual>
    <collision>
      <geometry>
        <sphere radius="0.015"/>
      </geometry>
      <origin rpy="0 0 0" xyz="0 0 0"/>
    </collision>
    <inertial>
      <mass value="0.1"/>
      <origin xyz="0 0 0"/>
      <inertia ixx="0.0001" ixy="0.0" ixz="0.0" iyy="0.0001" iyz="0.0" izz="0.0001"/>
    </inertial>
  </link>
  <!-- Caster Joint -->
  <joint name="caster_rear_left_joint" type="fixed">
    <parent link="base_link"/>
    <child link="caster_rear_left_link"/>
    <origin rpy="0 0 0" xyz="-0.15925 0.121 -0.0008"/>
  </joint>
  <gazebo reference="caster_rear_left_link">
    <material>Gazebo/DarkGrey</material>
    <turnGravityOff>false</turnGravityOff>
    <mu1 value="0.1"/>
    <mu2 value="0.1"/>
    <kp value="10000000.0"/>
    <kd value="1.0"/>
  </gazebo>
  <joint name="imu_joint" type="fixed">
    <parent link="base_link"/>
    <child link="imu"/>
    <origin rpy="0 0 0" xyz="0 0 0.109525"/>
  </joint>
  <link name="imu">
    <inertial>
      <mass value="0.001"/>
      <origin rpy="0 0 0" xyz="0 0 0"/>
      <inertia ixx="1e-09" ixy="0.0" ixz="0.0" iyy="1e-09" iyz="0.0" izz="1e-09"/>
    </inertial>
  </link>
  <gazebo>
    <plugin filename="libgazebo_ros_imu.so" name="imu_plugin">
      <alwaysOn>true</alwaysOn>
      <robotNamespace>/</robotNamespace>
      <updateRate>50</updateRate>
      <bodyName>imu</bodyName>
      <frameId>imu</frameId>
      <frameName>imu</frameName>
      <topicName>imu/data</topicName>
      <xyzOffset>0.0 0.0 0.0</xyzOffset>
      <rpyOffset>0.0 0.0 0.0</rpyOffset>
      <headingDrift>0.0005</headingDrift>
      <gaussianNoise>0.0005</gaussianNoise>
    </plugin>
  </gazebo>
  <!-- lidar link -->
  <link name="lidar">
    <visual>
      <origin rpy="0 0 0.785398" xyz="0 0 -0.03"/>
      <geometry>
        <mesh filename="package://volta_description/meshes/rplidar.dae"/>
      </geometry>
    </visual>
    <collision>
      <origin rpy="0 0 0" xyz="0 0 -0.03"/>
      <geometry>
        <mesh filename="package://volta_description/meshes/rplidar.dae"/>
      </geometry>
    </collision>
    <inertial>
      <origin rpy="0 0 0" xyz="0 0 -0.005"/>
      <mass value="0.3"/>
      <inertia ixx="0.00028" ixy="0.0" ixz="0.0" iyy="0.00028" iyz="0.0" izz="0.00022"/>
    </inertial>
  </link>
  <!-- lidar joint -->
  <joint name="lidar_joint" type="fixed">
    <origin rpy="0 0 0" xyz="0.1995 0.0 0.144"/>
    <parent link="base_link"/>
    <child link="lidar"/>
  </joint>
  <gazebo reference="lidar">
    <sensor name="lidar" type="ray">
      <always_on>true</always_on>
      <pose>0 0 0 0 0 0</pose>
      <visualize>false</visualize>
      <update_rate>50</update_rate>
      <ray>
        <scan>
          <horizontal>
            <samples>271</samples>
            <resolution>1</resolution>
            <min_angle>-1.57</min_angle>
            <max_angle>1.57</max_angle>
          </horizontal>
        </scan>
        <range>
          <min>0.5</min>
          <max>10.0</max>
          <resolution>0.01</resolution>
        </range>
      </ray>
      <plugin filename="libgazebo_ros_laser.so" name="gazebo_ros_laser">
        <topicName>scan_filtered</topicName>
        <frameName>lidar</frameName>
        <robotNamespace>/</robotNamespace>
        <gaussianNoise>0.005</gaussianNoise>
        <alwaysOn>true</alwaysOn>
      </plugin>
    </sensor>
  </gazebo>
  <!-- Camera link -->
  <link name="camera">
    <visual>
      <origin rpy="0 0 0" xyz="0 0 -0.0125"/>
      <geometry>
        <mesh filename="package://volta_description/meshes/d435i.dae"/>
      </geometry>
    </visual>
    <collision>
      <origin rpy="0 0 0" xyz="0 0 -0.0125"/>
      <geometry>
        <mesh filename="package://volta_description/meshes/d435i.dae"/>
      </geometry>
    </collision>
    <inertial>
      <mass value="0.162"/>
      <origin rpy="0 0 0" xyz="-0.003 0 0.0"/>
      <inertia ixx="0.00011" ixy="0.0" ixz="0.0" iyy="0.00005" iyz="0.0" izz="0.00011"/>
    </inertial>
  </link>
  <!-- Camera joint -->
  <joint name="base_to_camera" type="fixed">
    <parent link="base_link"/>
    <child link="camera"/>
    <origin xyz="0.2285 0.0 0.206"/>
  </joint>
  <gazebo reference="camera">
    <sensor name="camera" type="camera">
      <update_rate>50</update_rate>
      <camera name="head">
        <horizontal_fov>1.3962634</horizontal_fov>
        <image>
          <width>1080</width>
          <height>720</height>
          <format>R8G8B8</format>
        </image>
        <clip>
          <near>0.02</near>
          <far>300</far>
        </clip>
        <noise>
          <type>gaussian</type>
          <mean>0.0</mean>
          <stddev>0.007</stddev>
        </noise>
      </camera>
      <plugin filename="libgazebo_ros_camera.so" name="camera_controller">
        <!-- <robotNamespace>${robot_namespace}</robotNamespace> -->
        <alwaysOn>true</alwaysOn>
        <updateRate>50</updateRate>
        <cameraName>camera</cameraName>
        <imageTopicName>camera</imageTopicName>
        <cameraInfoTopicName>camera_info</cameraInfoTopicName>
        <frameName>camera</frameName>
        <hackBaseline>0.07</hackBaseline>
        <distortionK1>0.0</distortionK1>
        <distortionK2>0.0</distortionK2>
        <distortionK3>0.0</distortionK3>
        <distortionT1>0.0</distortionT1>
        <distortionT2>0.0</distortionT2>
      </plugin>
    </sensor>
  </gazebo>
  <!-- Robot Gazebo tag -->
  <gazebo>
    <plugin filename="libgazebo_ros_control.so" name="gazebo_ros_control">
      <robotNamespace>/</robotNamespace>
      <robotSimType>gazebo_ros_control/DefaultRobotHWSim</robotSimType>
    </plugin>
  </gazebo>
</robot>

